Traceback (most recent call last):
  File "/hpc/home/jjm132/jjm132/nlp4neuro/code/experiment_5/experiment_5.py", line 431, in <module>
    run_self_supervised_experiment()
  File "/hpc/home/jjm132/jjm132/nlp4neuro/code/experiment_5/experiment_5.py", line 326, in run_self_supervised_experiment
    train_cpc(model_gpt2, train_loader, val_loader, device, num_epochs=num_epochs,
  File "/hpc/home/jjm132/jjm132/nlp4neuro/code/experiment_5/experiment_5.py", line 89, in train_cpc
    loss = info_nce_loss(z, c, prediction_step=prediction_step)
  File "/hpc/home/jjm132/jjm132/nlp4neuro/code/experiment_5/experiment_5.py", line 63, in info_nce_loss
    c_t_expanded = c_t.unsqueeze(1).expand(-1, B * T, -1).contiguous().view(B * T, latent_dim)
RuntimeError: shape '[160, 128]' is invalid for input of size 655360
